Workbook

Sheet Question 
B2: The Trial Balance BBS Limited contained the following accounts at December 31, 2018, the end of company's fiscal year.
B4: SL. | C4: Account Titles | D4: Debit | E4: Credit
B5: 1 | C5: Cash | D5: 28700
B6: 2 | C6: Accounts Receivable | D6: 30700 | G6: Additional Data:
B7: 3 | C7: Land | D7: 600000 | G7: 1 | H7: The company is under 42.5% tax bracket.
B8: 4 | C8: Merchandise Inventory | D8: 44700 | G8: 2 | H8: The interest on the debentures has not yet been paid.
B9: 5 | C9: Supplies | D9: 6200 | G9: 3 | H9: The company has declared 10% cash dividend on the 50,000 ordinary shares.
B10: 6 | C10: Machinery | D10: 85000 | G10: 4 | H10: Depreciation is to be charged on a reducing-balance basis: machinery at 20%, equipment at 10%.
B11: 7 | C11: Accumulated Depreciation-Machinery | E11: 22000 | G11: 5 | H11: Supplies on hand totaled $2000.
B12: 8 | C12: Equipment | D12: 48000
B13: 9 | C13: Accumulated Depreciation-Equipment | E13: 6000 | G13: Required: Prepare a multiple step income statement for the year ended December 31, 2018, a statement of stockholders’ equity for the year ended December 31, 2018 and a classified balance sheet as at December 31, 2018 for BBS Limited.
B14: 10 | C14: Gain on sale of the propertry | E14: 51000
B15: 11 | C15: 8% Debenture | E15: 100000
B16: 12 | C16: Accounts Payable | E16: 48500
B17: 13 | C17: Common Stock (50,000 shares of $2 each) | E17: 100000
B18: 14 | C18: Additional Paid in Capital | E18: 220000
B19: 15 | C19: Retained Earnings | E19: 50000 | I19: =E31-D31 -> 0
B20: 16 | C20: Sales | E20: 1755200
B21: 17 | C21: Sales Returns and Allowances | D21: 8800
B22: 18 | C22: Cost of Goods Sold | D22: 897400
B23: 19 | C23: Salaries Expense | D23: 24400
B24: 20 | C24: Adveritising Expense | D24: 14000
B25: 21 | C25: Utilities Expense | D25: 12100
B26: 22 | C26: Repair Expense | D26: 24000
B27: 23 | C27: Wages Expense | D27: 16700
B28: 24 | C28: Freight Out Expense | D28: 2400
B29: 25 | C29: Rent Expense | D29: 207200
B30: 26 | C30: Auditors Fee | D30: 302400
C31: Total | D31: =SUM(D5:D30) -> 2352700 | E31: =SUM(E5:E30) -> 2352700 | H31: =E31-D31 -> 0

Sheet Solution 
B1: BBS Company Limited
B2: Income Statement
B3: For the year ended December 31,2018
B4: Sales | E4: ='Question '!E20 -> 1755200
B5: Less: Sales Returns and Allowances | E5: =-('Question '!D21) -> -8800
B6: Net Sales | F6: =E4+E5 -> 1746400
B7: Less: Cost of Goods Sold | F7: =-'Question '!D22 -> -897400
D8: Gross Profit | F8: =F6+F7 -> 849000
B9: Less: Operating Expense
B10: Salaries Expense | E10: 24400
B11: Adveritising Expense | E11: 14000
B12: Utilities Expense | E12: 12100
B13: Repair Expense | E13: 24000
B14: Wages Expense | E14: 16700
B15: Freight Out Expense | E15: 2400
B16: Rent Expense | E16: 207200
B17: Supplies Expense (6200-2000) (A 5) | E17: =6200-2000 -> 4200
B18: Auditors Fee | E18: 302400
B19: Depreciation Expense-Machinery (85,000-22,000)*20% (A 4) | E19: 12600
B20: Depreciation Expense-Equipment (48,000-6,000)*10% (A 4) | E20: 4200
B21: Total Operating Expenses | F21: =-SUM(E10:E20) -> -624200
C22: Income from Operation/Operating Income | F22: =F8+F21 -> 224800
B23: Add: Other Income
B24: Gain on sale of propertry | E24: ='Question '!E14 -> 51000
B25: Less: Other Expenses
F26: =SUM(E24:E26) -> 51000
C27: Earnings before interest and taxes (EBIT) | F27: =F22+F26 -> 275800
B28: Less: Interest Expense (100,000*8%) (A 2) | F28: -8000
C29: Earnings before taxes | F29: =F27+F28 -> 267800
B30: Less: Taxes (267800*42.5%) (A 1) | F30: =-(F29*0.425) -> -113815
C31: Net Income | F31: =F29+F30 -> 153985
B33: BBS Company Limited
B35: Statement of Stockholder's Equity
B36: For the year ended December 31,2018
E37: Common Stock | F37: Additional Paid in Capital-Common Stock | G37: Retained Earnings | H37: Total
B38: Balance, January 1,2018 | E38: 100000 | F38: 220000 | G38: 50000 | H38: =SUM(E38:G38) -> 370000
B39: Add: Net Income of the year 2018 | G39: =F31 -> 153985 | H39: =SUM(E39:G39) -> 153985
B40: Less: Cash Dividend Declared (100000*10%) (A 3) | G40: -10000 | H40: =SUM(E40:G40) -> -10000
B42: Balance, December 31,2018 | E42: =SUM(E38:E41) -> 100000 | F42: =SUM(F38:F41) -> 220000 | G42: =G38+G39+G40 -> 193985 | H42: =SUM(H38:H41) -> 513985
B46: BBS Company Limited
...
