Workbook

Sheet Format of Financial Statements
B1: ABC Limited
B2: Income Statement
B3: For the year ended December 31,2018
B4: Sales | E4: XXX
B5: Less: Sales Returns and Allowances | E5: (XXX)
B6: Less: Sales Discount | E6: (XXX)
B7: Net Sales | F7: XXX
B8: Cost of Goods Sold | F8: (XXX)
D9: Gross Profit | F9: XXX
B10: Less: Operating Expense
B11: Salaries Expense | E11: XXX
B12: Adveritising Expense | E12: XXX
B13: Utilities Expense | E13: XXX
B14: Repair Expense | E14: XXX
B15: Wages Expense | E15: XXX
B16: Freight Out Expense | E16: XXX
B17: Rent Expense | E17: XXX
B18: Supplies Expense | E18: XXX
B19: Auditors Fee | E19: XXX
B20: Depreciation Expense-Machinery | E20: XXX
B21: Depreciation Expense-Equipment | E21: XXX
B22: Etc………………………………………………………….
B23: Total Operating Expenses | F23: (XXX)
C24: Income from Operation/Operating Income | F24: XXX
B25: Add: Other Income
B26: Interest Income | E26: XXX
B27: Gain on sale of propertry etc………….. | E27: XXX
B28: Less: Other Expenses
B29: Loss on sale of property | E29: (XXX)
B30: Casualty Losses etc. | E30: (XXX)
F31: XXX
C32: Earnings before interest and taxes (EBIT) | F32: XXX
B33: Less: Interest Expense | F33: (XXX)
C34: Earnings before taxes (EBT) | F34: XXX
B35: Less: Taxes | F35: (XXX)
C36: Net Income/Earnings after Taxes (EAT) | F36: XXX
B38: ABC Limited
B40: Statement of Stockholder's Equity
B41: For the year ended December 31,2018
E42: Common Stock | F42: Additional Paid in Capital | G42: Retained Earnings | H42: Total
...

Sheet Sample Question 1
C2: The Trial Balance BBS Limited contained the following accounts at December 31, 2018, the end of company's fiscal year.
D4: Debit | E4: Credit
B5: 1 | C5: Cash | D5: 28700
B6: 2 | C6: Accounts Receivable | D6: 30700
B7: 3 | C7: Land | D7: 600000
B8: 4 | C8: Merchandise Inventory | D8: 44700
B9: 5 | C9: Supplies | D9: 6200
B10: 6 | C10: Machinery | D10: 85000
B11: 7 | C11: Accumulated Depreciation-Machinery | E11: 22000
B12: 8 | C12: Equipment | D12: 48000
B13: 9 | C13: Accumulated Depreciation-Equipment | E13: 6000
B14: 10 | C14: Gain on sale of the propertry | E14: 51000
B15: 11 | C15: 8% Debenture | E15: 100000
B16: 12 | C16: Accounts Payable | E16: 48500
B17: 13 | C17: Common Stock (50,000 shares of $2 each) | E17: 100000
B18: 14 | C18: Additional Paid in Capital | E18: 220000
B19: 15 | C19: Retained Earnings | E19: 50000 | I19: =E31-D31 -> 0
B20: 16 | C20: Sales | E20: 1755200
B21: 17 | C21: Sales Returns and Allowances | D21: 8800
B22: 18 | C22: Cost of Goods Sold | D22: 897400
B23: 19 | C23: Salaries Expense | D23: 24400
B24: 20 | C24: Adveritising Expense | D24: 14000
B25: 21 | C25: Utilities Expense | D25: 12100
B26: 22 | C26: Repair Expense | D26: 24000
B27: 23 | C27: Wages Expense | D27: 16700
B28: 24 | C28: Freight Out Expense | D28: 2400
B29: 25 | C29: Rent Expense | D29: 207200
B30: 26 | C30: Auditors Fee | D30: 302400
C31: Total | D31: =SUM(D5:D30) -> 2352700 | E31: =SUM(E5:E30) -> 2352700 | H31: =E31-D31 -> 0
C33: Additional Data:
B34: 1 | C34: The company is under 42.5% tax bracket.
B35: 2 | C35: The interest on the debentures has not yet been paid.
B36: 3 | C36: A cash dividend of $1 has been declared on the 50,000 ordinary shares.
B37: 4 | C37: Depreciation is to be charged on a reducing-balance basis: equipment at 10%, machinery at 20%.
B38: 5 | C38: Supplies on hand totaled $2000.

Sheet Solution to the question 1
B1: BBS Company Limited
B2: Income Statement
B3: For the year ended December 31,2018
B4: Sales | E4: ='Sample Question 1'!E20 -> 1755200
B5: Less: Sales Returns and Allowances | E5: ='Sample Question 1'!D21 -> 8800
B6: Net Sales | F6: =E4-E5 -> 1746400
B7: Cost of Goods Sold | F7: ='Sample Question 1'!D22 -> 897400
D8: Gross Profit | F8: =F6-F7 -> 849000
B9: Less: Operating Expense
B10: Salaries Expense | E10: 24400
B11: Adveritising Expense | E11: 14000
B12: Utilities Expense | E12: 12100
B13: Repair Expense | E13: 24000
B14: Wages Expense | E14: 16700
B15: Freight Out Expense | E15: 2400
B16: Rent Expense | E16: 207200
B17: Supplies Expense (6200-2000) | E17: =6200-2000 -> 4200
B18: Auditors Fee | E18: 302400
B19: Depreciation Expense-Machinery | E19: 12600
B20: Depreciation Expense-Equipment | E20: 4200
B21: Total Operating Expenses | F21: =SUM(E10:E20) -> 624200
C22: Income from Operation/Operating Income | F22: =F8-F21 -> 224800
B23: Add: Other Income
B24: Gain on sale of propertry | E24: ='Sample Question 1'!E14 -> 51000
B25: Less: Other Expenses
F26: =SUM(E24:E26) -> 51000
C27: Earnings before interest and taxes (EBIT) | F27: =F22+F26 -> 275800
B28: Less: Interest Expense (100,000*8%) | F28: 8000
C29: Earnings before taxes | F29: =F27-F28 -> 267800
B30: Less: Taxes (267800*42.5%) | F30: =F29*0.425 -> 113815
C31: Net Income | F31: =F29-F30 -> 153985
B33: BBS Company Limited
B35: Statement of Stockholder's Equity
B36: For the year ended December 31,2018
E37: Common Stock | F37: Additional Paid in Capital | G37: Retained Earnings | H37: Total
B38: Balance, January 1,2018 | E38: 100000 | F38: 220000 | G38: 50000 | H38: =SUM(E38:G38) -> 370000
B39: Add: Net Income of the year 2018 | G39: =F31 -> 153985 | H39: =SUM(E39:G39) -> 153985
B40: Less: Cash Dividend | G40: -50000 | H40: =SUM(E40:G40) -> -50000
B42: Balance, December 31,2018 | E42: =SUM(E38:E41) -> 100000 | F42: =SUM(F38:F41) -> 220000 | G42: =SUM(G38:G41) -> 153985 | H42: =SUM(H38:H41) -> 473985
B46: BBS Company Limited
...

Sheet Sample Question 2
B2: The Trial Balance ABC Limited contained the following accounts at December 31, 2018, the end of company's fiscal year.
C3: Debit | D3: Credit
A4: 1 | B4: Cash | C4: 37700
A5: =1+A4 -> 2 | B5: Accounts Receivable | C5: 111600
A6: =1+A5 -> 3 | B6: Merchandise Inventory | C6: 180000
A7: =1+A6 -> 4 | B7: Office Supplies | C7: 5000
A8: =1+A7 -> 5 | B8: Prepaid Insurance | C8: 12000
A9: =1+A8 -> 6 | B9: Office Equipment | C9: 115200
A10: =1+A9 -> 7 | B10: Accumulated Depreciation-Office Equipment | D10: 49500
A11: =1+A10 -> 8 | B11: Store Equipment | C11: 311500
A12: =1+A11 -> 9 | B12: Accumulated Depreciation-Store Equipment | D12: 87500
A13: =1+A12 -> 10 | B13: Patent | C13: 300000
A14: =1+A13 -> 11 | B14: Accounts Payable | D14: 48600
A15: =1+A14 -> 12 | B15: 10% Bonds | D15: 54000
A16: =1+A15 -> 13 | B16: Common Stock (50,000 shares of $4 par) | D16: 200000
A17: =1+A16 -> 14 | B17: Additional Paid in Capital-Common Stock | D17: 209800
A18: =1+A17 -> 15 | B18: Retained Earnings | D18: 345000
A19: =1+A18 -> 16 | B19: Sales | D19: 2703600
A20: =1+A19 -> 17 | B20: Sales Salaries Expense | C20: 378000
A21: =1+A20 -> 18 | B21: Sales Returns and Allowances | C21: 37800
A22: =1+A21 -> 19 | B22: Sales Discount | C22: 19800
A23: =1+A22 -> 20 | B23: Cost of Goods Sold | C23: 1926000
A24: =1+A23 -> 21 | B24: Advertising Expense | C24: 50900
A25: =1+A24 -> 22 | B25: Office Salaries Expense | C25: 73800
A26: =1+A25 -> 23 | B26: Rent Expense | C26: 102300
A27: =1+A26 -> 24 | B27: Utlities Expense | C27: 16500
A28: =1+A27 -> 25 | B28: Loss on Sale of Office Equipment | C28: 22900
A29: =1+A28 -> 26 | B29: Interest Revenue | D29: 16000
A30: =1+A29 -> 27 | B30: Auditors Fees | C30: 13000
B31: Total | C31: =SUM(C4:C30) -> 3714000 | D31: =SUM(D4:D30) -> 3714000
B33: Additional Data:
B34: 1. The company is under 32.5% tax bracket.
B35: 2. The interest accrued on the Bond has not been paid yet.
B36: 3. A 10% Cash dividend has been declared on the common stock.
B37: 4. Depreciation @ 20% is to be charged on Office Equipment under reducing-balance method. However, for the Store Equipment straight line method is used where depreciation is charged @10%.
B38: 5. The prepaid insurance was paid for 2 years on September 1, 2018.
B39: 6. The physical inventory check reveals that Merhcandise Inventory actually at hand is $ 175,000.
B42: cogs 5000
B43: inventory cr. 5000
B45: if inventory is 185000
...

Sheet Solution to the question 2
B1: ABC Company Limited
B2: Income Statement
B3: For the year ended December 31,2018
B4: Sales | E4: 2703600
B5: (-) Sales Return and Allowances | E5: -37800
B6: (-) Sales Discount | E6: -19800
C7: Net Sales | F7: =SUM(E4:E6) -> 2646000
B8: Cost of Goods Sold (1,926,000+5,000) | F8: =-(1926000+5000) -> -1931000
C9: Gross Profit | F9: =F7+F8 -> 715000
B10: Operating Expenses:
B11: Sales Salaries Expense | E11: 378000
B12: Adveritising Expense | E12: 50900
B13: Office Salaries Expense | E13: 73800
B14: Rent Expense | E14: 102300
B15: Utilities Expense | E15: 16500
B16: Auditors Fee | E16: 13000
B17: Depreciation Expense-Office Equipment (65,700*20%) | E17: =13140 -> 13140
B18: Depreciation Expense-Store Equipment (311,500*10%) | E18: 31150
B19: Insurance Expense (12,000*4/24) | E19: 2000
C21: Total Operating Expenses | F21: =SUM(E11:E19) -> 680790
C22: Operating Income | F22: =F9-F21 -> 34210
B23: Add: Other Income
B24: Interest Revenue | E24: 16000
B26: Less: Other Expense
B27: Loss on Sale of Property | E27: -22900 | F27: =E24+E27 -> -6900
C28: EBIT | F28: =F22+F27 -> 27310
B29: (-) Interest Expense (54,000*10%) | F29: 5400
C30: EBT | F30: =F28-F29 -> 21910
B31: (-) Tax Expense (21910*32.5%) | F31: =F30*0.325 -> 7120.75
C32: Net Income | F32: =F30-F31 -> 14789.25
B34: ABC Company Limited
B36: Statement of Stockholders's Equity
B37: For the year ended December 31,2018
E38: Common Stock | F38: Additional Paid in Capital | G38: Retained Earnings | H38: Total
B39: Balance January 1, 2018 | E39: 200000 | F39: 209800 | G39: 345000 | H39: =SUM(E39:G39) -> 754800
B40: (+) Net Income of the year | G40: =F32 -> 14789.25 | H40: =SUM(E40:G40) -> 14789.25
B41: (-) Cash Dividend (200,000*10%) | G41: -20000 | H41: =SUM(E41:G41) -> -20000
E43: =SUM(E39:E42) -> 200000 | F43: =SUM(F39:F42) -> 209800 | G43: =SUM(G39:G42) -> 339789.25 | H43: =SUM(E43:G43) -> 749589.25
B47: ABC Company Limited
B48: Balance Sheet
...

Sheet Sample Question 3 
A1: Sa
D3: The ledger of EEE Limited contained the following account balances at December 31, 2018, the end of company's fiscal year.
E4: Balances
D5: Cash | E5: 7540
D6: Accounts Receivable | E6: 22320
D7: Inventory | E7: 36000
D8: Supplies | E8: 1000
D9: Prepaid Rent | E9: 9400
D10: Machinery | E10: 23040
D11: Accumulated Depreciation-Machinery | E11: 9900
D12: Equipment | E12: 62300
D13: Accumulated Depreciation-Equipment | E13: 7500
D14: Land | E14: 70000
D15: Accounts Payable | E15: 9720
D16: 15% Debenture | E16: 30800
... D31: Other Administrative Expense | E31: 2600
I32: =F32*2 -> 0
D34: Additional Data:
D35: 1. The accountant has forgot to record the issue of 1,000 common share @ $4.5 each on December 21, 2018.
D36: 2. 10% cash Dividend has been declared on the common stock.
D37: 3. The company is under 30% tax bracket.
D38: 4. Machinery is being depreciated @20% under straight line method,Equipment is being depreciated @30% under reducing balance method.
D39: 5. Supplies actually on hand is $ 200.
D40: 6. Physical check on December 31, 2018 reveals that inventory actually on hand is $ 35,200.
D43: cash 4500
D44: common stock 2500
D45: add com stock 2000

Sheet Solution to the question 3
B1: EEE Company Limited
B2: Income Statement
B3: For the year ended December 31,2018
B4: Sales | E4: 540720
B5: (-)Sales Returns and allowances | E5: 7560
B6: (-) Sales Discount | E6: 3960
C7: Net Sales | F7: =E4-E5-E6 -> 529200
B8: (-) Cost of Goods Sold (385,200+800) | F8: =385200+800 -> 386000
C9: Gross Profit | F9: =F7-F8 -> 143200
B11: Less: Operating Expenses
B12: Supplies Expense (1000-200) | E12: 800
B13: Salaries Expense | E13: 75600
B14: Wages Expense | E14: 7760
B15: Rent Expense | E15: 10460
B16: Advertising Expense | E16: 10180
B17: Other Administrative Expenses | E17: 2600
B18: Depreciation Expense-Machinery (23040*20%) | E18: =23040*0.2 -> 4608
B19: Depreciation Expense-Equipment (54,800*30%) | E19: =54800*0.3 -> 16440
B21: Total Operating Expenses | F21: =SUM(E12:E19) -> 128448
C22: Income from Operation | F22: =F9-F21 -> 14752
B23: Add: Other Income
B24: Rent Revenue | E24: 3200
B26: Less: Other Expenses
B27: Loss from employee strike | E27: -4580 | F27: =E24+E27 -> -1380
C28: Earnings Before Interest and Tax (EBIT) | F28: =F22+F27 -> 13372
B29: (-) Interest Expense (3300+1320) | F29: 4620
C30: Earnings Before Tax (EBT) | F30: =F28-F29 -> 8752
B31: (-) Tax (8752*30%) | F31: =F30*0.3 -> 2625.6
C32: Net Income | F32: =F30-F31 -> 6126.4
B34: EEE Company Limited
B36: Statement of Stockholder's Equity
B37: For the year ended December 31,2018
E38: Common Stock | F38: Additional Paid in Capital | G38: Retained Earnings | H38: Total
B39: Balance, January 1, 2018 | E39: 40000 | F39: 41960 | G39: 59000 | H39: =SUM(E39:G39) -> 140960
B40: Issuance of Common Stock | E40: 2500 | F40: 2000 | H40: =SUM(E40:G40) -> 4500
B41: (+) Net Income of 2018 | G41: =F32 -> 6126.4 | H41: =SUM(E41:G41) -> 6126.4
B42: (-) Cash Dividend Declared (42,500*0.10) | G42: 4250 | H42: =SUM(E42:G42) -> 4250
E43: =SUM(E39:E42) -> 42500 | F43: =SUM(F39:F42) -> 43960 | G43: =G39+G41-G42 -> 60876.4 | H43: =SUM(E43:G43) -> 147336.4
B47: EEE Company Limited
B48: Balance Sheet
...

Sheet Sample Question 4
B2: The ledger of Corcord PropertiesLimited contained the following account balances at December 31, 2021, the end of company's fiscal year.
B3: Particulars | C3: Debit | D3: Credit
B4: Cash | C4: 34200
B5: Merchandise Inventory | C5: 111000
B6: Accounts Receivable | C6: 190000
B7: Office Supplies | C7: 4000
B8: Prepaid Insurance | C8: 15000
B9: Store Equipment | C9: 115200
B10: Accumulated Depreciation-Store Equipment | D10: 40400
B11: Office Equipment | C11: 320000
B12: Accumulated Depreciation-Office Equipment | D12: 65900
B13: Patent | C13: 250000
B14: 10% Bonds | D14: 37000
B15: Accounts Payable | D15: 49000
B16: Common Stock (50,000 shares of $5 par) | D16: 250000
B17: Additional Paid in Capital-Common Stock | D17: 180000
B18: Retained Earnings | D18: 360000
B19: Sales | D19: 3045600
B20: Sales Salaries Expense | C20: 398000
B21: Sales Returns and Allowances | C21: 34500
B22: Sales Discount | C22: 17200
B23: Cost of Goods Sold | C23: 2223000
B24: Office Salaries Expense | C24: 48750
B25: Advertising Expense | C25: 74400
B26: Rent Expense | C26: 120400
B27: Utlities Expense | C27: 32700
B28: Auditors Fees | C28: 35900
B29: Interest Revenue | D29: 12350
B30: Loss on Sale of Office Equipment | C30: 16000
B31: Total | C31: =SUM(C4:C30) -> 4040250 | D31: =SUM(D4:D30) -> 4040250
B33: Additional Data:
B34: 1. Store Equipment is being depreciated @20% under straight line method, Office Equipment is being depreciated @30% under reducing balance method.
B35: 2. Supplies actually on hand is $ 800.
B36: 3. Physical check on December 31, 2018 reveals that inventory actually on hand is $ 109,500.
B37: 4. The accountant has forgot to record the issue of 1,000 common share @ $6 each on December 21, 2021.
B38: 5. 20% cash Dividend has been declared on the common stock.
B39: 6. The company is under 35% tax bracket.

Sheet Solution 4
B1: EEE Company Limited
B2: Income Statement
B3: For the year ended December 31,2018
B4: Sales | E4: 3045600
B5: (-)Sales Returns and allowances | E5: 34500
B6: (-) Sales Discount | E6: 17200
C7: Net Sales | F7: =E4-E5-E6 -> 2993900
B8: (-) Cost of Goods Sold (2223000+1500) | F8: =SUM(2223000+1500) -> 2224500
C9: Gross Profit | F9: =F7-F8 -> 769400
B11: Less: Operating Expenses
B12: Sales Salaries Exp | E12: 398000
B13: Supplies Expense (4000-800) | E13: 3200
B14: Office Salaries Expense | E14: 48750
B15: Rent Expense | E15: 120400
B16: Advertising Expense | E16: 74400
B17: Utilities Exp | E17: 32700
B18: Auditors Fee | E18: 35900
B19: Depreciation Expense-Store Equipment (1152000*20%) | E19: =115200*0.2 -> 23040
B20: Depreciation Expense-Equipment (254,100*30%) | E20: =254100*0.3 -> 76230
B22: Total Operating Expenses | F22: =SUM(E12:E20) -> 812620
C23: Income from Operation | F23: =F9-F22 -> -43220
B24: Add: Other Income
B25: Interest Revenue | E25: 12350
B27: Less: Other Expenses
B28: Loss on sale of office equipment | E28: -16000 | F28: =E25+E28 -> -3650
C29: Earnings Before Interest and Tax (EBIT) | F29: =F23+F28 -> -46870
B30: (-) Interest Expense (3700) | F30: 3700
C31: Earnings Before Tax (EBT) | F31: =F29-F30 -> -50570
B32: (-) Tax (50570*35%) | F32: =F31*0.35 -> -17699.5
C33: Net Loss | F33: =F31+F32 -> -68269.5
B35: EEE Company Limited
B37: Statement of Stockholder's Equity
B38: For the year ended December 31,2018
E39: Common Stock | F39: Additional Paid in Capital | G39: Retained Earnings | H39: Total
B40: Balance, January 1, 2018 | E40: 250000 | F40: 180000 | G40: 360000 | H40: =SUM(E40:G40) -> 790000
B41: Issuance of Common Stock | E41: 5000 | F41: 1000 | H41: =SUM(E41:G41) -> 6000
B42: (+) Net Income of 2018 (loss) | G42: =F33 -> -68269.5 | H42: =SUM(E42:G42) -> -68269.5
B43: (-) Cash Dividend Declared (2,55000*0.20) | G43: 51000 | H43: =SUM(E43:G43) -> 51000
E44: =SUM(E40:E43) -> 255000 | F44: =SUM(F40:F43) -> 181000 | G44: 240730 | H44: =SUM(E44:G44) -> 676730
B48: EEE Company Limited
...

Sheet Sample Question 5
B2: The ledger of New Hope Limited contained the following account balances at December 31, 2021, the end of company's fiscal year.
B3: Particulars | C3: Debit | D3: Credit
B4: Cash | C4: 67500
B5: Merchandise Inventory | C5: 160000
B6: Accounts Receivable | C6: 210000
B7: Office Supplies | C7: 6300
B8: Prepaid Insurance | C8: 25000
B9: Furniture | C9: 120000
B10: Accumulated Depreciation-Furniture | D10: 36000
B11: Office Equipment | C11: 400000
B12: Accumulated Depreciation-Office Equipment | D12: 200000
B13: Patent | C13: 180000
B14: 10% Bonds | D14: 56000
B15: Accounts Payable | D15: 34250
B16: Common Stock (70,000 shares of $3 par) | D16: 210000
B17: Additional Paid in Capital-Common Stock | D17: 160000
B18: Retained Earnings | D18: 422000
B19: Sales | D19: 3100000
B20: Sales Salaries Expense | C20: 376500
B21: Sales Returns and Allowances | C21: 25400
B22: Sales Discount | C22: 13750
B23: Cost of Goods Sold | C23: 2345000
B24: Sale Executives Salaries Expense | C24: 54300
B25: Advertising Expense | C25: 88000
B26: Rent Expense | C26: 115000
B27: Utlities Expense | C27: 27600
B28: Entertainment Expense | C28: 33300
B29: Interest Revenue | D29: 14400
B30: Gain on Sale of Office Equipment | D30: 15000
B31: Total | C31: =SUM(C4:C30) -> 4247650 | D31: =SUM(D4:D30) -> 4247650 | F31: =D31-C31 -> 0
B33: Additional Data:
B34: 1. A 20% Cash dividend has been declared on the common stock.
B35: 2. Depreciation @ 25% is to be charged on Office Equipment under reducing-balance method. However, for the Furniture straight line method is used where depreciation is charged @15%.
B36: 3. The prepaid insurance was paid for 1 years on September 1, 2021.
B37: 4. The physical inventory check reveals that Merhcandise Inventory actually at hand is $ 155,000.
B38: 5. The company is under 35.5% tax bracket.
B39: 6. The interest accrued on the Bond has not been paid yet.
